<?xml version="1.0"?>
<robot xmlns:xacro="http://www.ros.org/wiki/xacro">

    <!-- Richiamiamo un file di macro per semplificare l'aggiunzione dei parametri di inerzia, l'origine da utilizzare
         per l'inerzia è quella contenuta nella sezione visual non quella nella sezione dei giunti ATTENZIONE,
         dove l'origine non viene specificata allora si lascia tutti zero-->

    <xacro:include filename="inertial_macros.xacro"/>

    <!-- Andiamo a definire i colori che avrà il nostro robot -->
    <!-- ovviamente i valori sono standard si possono trovare su internet -->

    <material name="white">
        <color rgba="1 1 1 1" />
    </material>

    <material name="orange">
        <color rgba="1 0.3 0.1 1" />
    </material>

    <material name="blue">
        <color rgba="0.2 0.2 1 1" />
    </material>

    <material name="black">
        <color rgba="0 0 0 1" />
    </material>


    <!-- Adesso iniziamo la sezione dove decriviamo i link che avrà il nostro robot, 
         per convenzione stabiliamo che il primo link venga chiamato "base_link"      -->


        <!-- Potrebbe essere intuitivo posizionare la terna base sul centro di massa del nostro robot,
             ma in realtà la scelta più conveniente risulta essere quella in mezzo all'asse che connette
             le due ruote, che risulta essere il centro attorno al quale il nostro robot sterza.
             Chiarito questo, definiremo tutte le altre terne a partire dalla terna BASE    --> 

         <link name="base_link">

         </link>


         <!-- Come prossimo obbiettivo dobbiamo stabilire le dimensioni del nostro robot,
              supporremo LARGHEZZA= 300 mm , LUNGHEZZA= 300 mm , ALTEZZA = 150 mm .
              Attenzione però che tutte le dimensioni dovranno essere riportate in metri,
              quindi continuiamo definendo il giunto telaio, nel quale all'interno definiremo
              il link di partenza (parent) e il link successivo (child).
              Imposteremo l'origine della terna chassis leggermente dietro la terna base per comodità   -->
        <!-- TERNA BASE -->

        <joint name="chassis_joint" type="fixed">
            <parent link="base_link"/>
            <child link="chassis"/>
            <origin xyz="-0.1 0 0"/>
        </joint>            

        <!-- Ovviamente adesso dobbiamo definire il link chassis, dove andremo ad impostare anche i parametri
             geometrici e fisici.
             Inoltre bisogna spostare la box perche se non impostassimo un'origine per la box questa sarebbe centrata
             alla terna e noi non la volevamo cosi quindi va settata anche l'origine   -->
        <!-- TELAIO -->

        <link name="chassis">
            <visual>
                <origin xyz="0.15 0 0.075"/>
                <geometry>
                    <box size="0.3 0.3 0.15"/>
                </geometry>
                <material name="white"/>
            </visual>
            <collision>
                <origin xyz="0.15 0 0.075"/>
                <geometry>
                    <box size="0.3 0.3 0.15"/>
                </geometry>
            </collision>
            <xacro:inertial_box mass="0.5" x="0.3" y="0.3" z="0.15">
                <origin xyz="0.15 0 0.075" rpy="0 0 0"/>
            </xacro:inertial_box>
        </link>

        <!-- Andiamo ad aggiungere le TAG per GAZEBO affinchè riesca a funzionare senza problemi, specifichiamo il colore-->

        <gazebo reference="chassis">
            <material>Gazebo/White</material>
        </gazebo>


        <!-- adesso iniziamo definendo le ruote del nostro robot, che connetteremo alla terna base,
             perche quella risulta essere il centro di rotazione del nostro robot e bisognerà
             specificare anche l'asse di rotazione  -->
        <!-- RUOTA SINISTRA -->

        <joint name="left_wheel_joint" type="continuous">
            <parent link="base_link"/>
            <child link="left_wheel"/>
            <origin xyz="0 0.175 0" rpy="-${pi/2} 0 0"/>
            <axis xyz="0 0 1"/>
        </joint>


        <!-- Per quanto riguarda i cilindri, quando vengono creati sono rivolti verso l'alto,
             noi vogliamo che il nostro cilindro abbia l'asse z orizzontale e rivolto verso
             l'esterno, quindi dovremo compiere una rotazione di 90° attorno ad x in verso orario--> 

        <link name="left_wheel">
            <visual>
                <geometry>
                    <cylinder radius="0.05" length="0.04"/>
                </geometry>
                <material name="blue"/>
            </visual>
            <collision>
                <geometry>
                    <cylinder radius="0.05" length="0.04"/>
                </geometry>
            </collision>
            <xacro:inertial_cylinder mass="0.1" length="0.04" radius="0.05">
                <origin xyz="0 0 0" rpy="0 0 0"/>
            </xacro:inertial_cylinder>
        </link>

        <gazebo reference="left_wheel">
            <material>Gazebo/Blue</material>
        </gazebo>


        <!-- RUOTA DESTRA -->

        <joint name="right_wheel_joint" type="continuous">
            <parent link="base_link"/>
            <child link="right_wheel"/>
            <origin xyz="0 -0.175 0" rpy="${pi/2} 0 0"/>
            <axis xyz="0 0 -1"/>
        </joint>


        <link name="right_wheel">
            <visual>
                <geometry>
                    <cylinder radius="0.05" length="0.04"/>
                </geometry>
                <material name="blue"/>
            </visual>
            <collision>
                <geometry>
                    <cylinder radius="0.05" length="0.04"/>
                </geometry>
            </collision>
            <xacro:inertial_cylinder mass="0.1" length="0.04" radius="0.05">
                <origin xyz="0 0 0" rpy="0 0 0"/>
            </xacro:inertial_cylinder>
        </link>
        
        <gazebo reference="right_wheel">
            <material>Gazebo/Blue</material>
        </gazebo>


        <!-- Adesso vogliamo realizzare la ruotina folle, prenderemo alcuni accorgimenti, cioè quello di considerarla senza attrito per semplicità,
             non è del tutto corretto, ma stiamo semplificando il problema-->


        <!-- RUOTA FOLLE -->

        <joint name="caster_wheel_joint" type="fixed">
            <parent link="chassis"/>
            <child link="caster_wheel"/>
            <origin xyz="0.24 0 0"/>
        </joint>

        <link name="caster_wheel">
            <visual>
                <geometry>
                    <sphere radius="0.05"/>
                </geometry>
                <material name="black"/>
            </visual>
            <collision>
                <geometry>
                    <sphere radius="0.05"/>
                </geometry>
            </collision>
            <xacro:inertial_sphere mass="0.1" radius="0.05">
                <origin xyz="0 0 0" rpy="0 0 0"/>
            </xacro:inertial_sphere>
        </link>

        <gazebo reference="caster_wheel">
            <material>Gazebo/Black</material>
            <!-- possiamo impostare anche i coefficenti di attrito per i link -->
            <mu1 value="0.001"/>
            <mu2 value="0.001"/>
        </gazebo>
        

</robot>